Workbook

Sheet bilans
C1: Bilans
E2: w tys. zł
D3: 2018 | E3: 2019 | F3: 2020
C4: AKTYWA
C5: I. Aktywa trwałe | D5: 89 906 | E5: 101 585 | F5: 108061
C6: 1. Wartości niematerialne i prawne, w tym: | D6: 5 426 | E6: 5 769 | F6: 4 348
C7: - wartość firmy | D7: 0 | E7: 0 | F7: 0
C8: 2. Rzeczowe aktywa trwałe | D8: 79 759 | E8: 92 037 | F8: 100 255
C9: 3. Należności długoterminowe | D9: 0 | E9: 0 | F9: 0
C10: 4. Inwestycje długoterminowe | D10: 1 354 | E10: 1 450 | F10: 1 450
C11: 4.1. Długoterminowe aktywa finansowe | D11: 1 354 | E11: 1 450 | F11: 1 450
C12: a) w jednostkach powiązanych, w tym: | D12: 1 354 | E12: 1 450 | F12: 1 450
C13: - udziały lub akcje w jednostkach zależnych wyceniane metodą praw własności | D13: 0 | E13: 0 | F13: 0
C14: 5. Długoterminowe rozliczenia międzyokresowe | D14: 3 367 | E14: 2 329 | F14: 2 008
C15: 5.1. Aktywa z tytułu odroczonego podatku dochodowego | D15: 2 411 | E15: 1 635 | F15: 1 645
C16: 5.2. Inne rozliczenia międzyokresowe | D16: 956 | E16: 694 | F16: 363
C17: II. Aktywa obrotowe | D17: 76 527 | E17: 73 183 | F17: 88 876
C18: 1. Zapasy | D18: 50 624 | E18: 50 778 | F18: 61 244
C19: 1.1 materiały | D19: 22329 | E19: 19038 | F19: 21586
C20: 1.2 produkty gotowe | D20: 24806 | E20: 29273 | F20: 33348
C21: 1.3 towary | D21: 3245 | E21: 2347 | F21: 6009
C22: 1.4 zaliczki na dostawy i usługi | D22: 244 | E22: 120 | F22: 301
C23: 2. Należności krótkoterminowe | D23: 18 003 | E23: 15 777 | F23: 19 352
C24: 2.1. Od jednostek powiązanych | D24: 3 498 | E24: 4 018 | F24: 2 988
C25: 2.2. Od pozostałych jednostek | D25: 14 505 | E25: 11 759 | F25: 16 364
C26: 3. Inwestycje krótkoterminowe | D26: 4 714 | E26: 2 354 | F26: 2 377
C27: 3.1. Krótkoterminowe aktywa finansowe | D27: 4 714 | E27: 2 354 | F27: 2 377
C28: a) środki pieniężne i inne aktywa pieniężne | D28: 4 714 | E28: 2 354 | F28: 2 377
C29: 4. Krótkoterminowe rozliczenia międzyokresowe | D29: 3 186 | E29: 4 274 | F29: 5 903
C30: A k t y w a r a z e m | D30: 166 433 | E30: 174 768 | F30: 196 937
C31: PASYWA
C32: I. Kapitał własny | D32: 111 812 | E32: 114 691 | F32: 132 445
C33: 1. Kapitał zakładowy | D33: 2 449 | E33: 2 470 | F33: 2 518
C34: 2. Kapitał zapasowy | D34: 70 354 | E34: 74 038 | F34: 99 029
C35: 3. Zysk (strata) netto | D35: 39 009 | E35: 38 183 | F35: 30 898
C36: II. Zobowiązania i rezerwy na zobowiązania | D36: 54 621 | E36: 60 077 | F36: 64 492
C37: 1. Rezerwy na zobowiązania | D37: 13 186 | E37: 9 852 | F37: 6 414
C38: 1.1. Rezerwa z tytułu odroczonego podatku dochodowego | D38: 3 106 | E38: 3 208 | F38: 3 612
C39: 1.2. Rezerwa na świadczenia emerytalne i podobne | D39: 6 321 | E39: 4 331 | F39: 1 237
C40: a) długoterminowa | D40: 218 | E40: 443 | F40: 310
...

Sheet rpp
A1: Rachunek przepływów pieniężnych
C2: w tys. zł
B3: 2018 | C3: 2019 | D3: 2020
A4: A. Przepływy środków pieniężnych z działalności operacyjnej
A5: I. Zysk (strata) netto | B5: 39 009 | C5: 38 183 | D5: 30 898
A6: II. Korekty razem | B6: 11 681 | C6: 3 418 | D6: -12 057
A7: 1. Amortyzacja | B7: 9 299 | C7: 11 463 | D7: 10 893
A8: 2. (Zyski) straty z tytułu różnic kursowych | B8: -297 | C8: 12 | D8: -56
A9: 3. Odsetki i udziały w zyskach (dywidendy) | B9: 347 | C9: 630 | D9: 340
A10: 4. (Zysk) strata z działalności inwestycyjnej | B10: 2 336 | C10: -1 548 | D10: -622
A11: 5. Zmiana stanu rezerw | B11: 7 514 | C11: -3 334 | D11: -3 438
A12: 6. Zmiana stanu zapasów | B12: -15 750 | C12: -155 | D12: -10 466
A13: 7. Zmiana stanu należności | B13: 1 445 | C13: 2 078 | D13: -3 111
A14: 8. Zmiana stanu zobowiązań krótkoterminowych, z wyjątkiem pożyczek i kredytów | B14: 11 019 | C14: -5 702 | D14: -5 935
A15: 9. Zmiana stanu rozliczeń międzyokresowych | B15: -4 205 | C15: -2 584 | D15: -2 806
A16: 10. Inne korekty | B16: -27 | C16: 2 558 | D16: 3 144
A17: III. Przepływy pieniężne netto z działalności operacyjnej (I+/-II) - metoda pośrednia | B17: 50 690 | C17: 41 601 | D17: 18 841
A18: B. Przepływy środków pieniężnych z działalności inwestycyjnej
A19: I. Wpływy | B19: 729 | C19: 963 | D19: 1 868
A20: 1. Zbycie wartości niematerialnych i prawnych oraz rzeczowych aktywów trwałych | B20: 302 | C20: 412 | D20: 1 651
A21: 2. Z aktywów finansowych, w tym: | B21: 300 | C21: 551 | D21: 0
A22: a) w jednostkach powiązanych | B22: 300 | C22: 551 | D22: 0
A23: - zbycie aktywów finansowych | B23: 300 | C23: 551 | D23: 0
A24: 3. Inne wpływy inwestycyjne | B24: 127 | C24: 0 | D24: 217
A25: II. Wydatki | B25: 22 283 | C25: 24 490 | D25: 17 811
A26: 1. Nabycie wartości niematerialnych i prawnych oraz rzeczowych aktywów trwałych | B26: 21 625 | C26: 23 694 | D26: 14 272
A27: 2. Inne wydatki inwestycyjne | B27: 658 | C27: 796 | D27: 3 539
A28: III. Przepływy pieniężne netto z działalności inwestycyjnej (I-II) | B28: -21 554 | C28: -23 527 | D28: -15 943
A29: C. Przepływy środków pieniężnych z działalności finansowej
A30: I. Wpływy | B30: 2 320 | C30: 19 236 | D30: 15 863
A31: Wpływy netto z emisji akcji (wydania udziałów) i innych instrumentów kapitałowych oraz dopłat do 1. kapitału | B31: 869 | C31: 909 | D31: 2 144
A32: 2. Kredyty i pożyczki | B32: 0 | C32: 17 405 | D32: 12 079
B33: w tys. zł | C33: w tys. zł
B34: 2018 | C34: 2019
A35: 3. Inne wpływy finansowe | B35: 1 451 | C35: 922 | D35: 1 640
A36: II. Wydatki | B36: 44 760 | C36: 39 657 | D36: 18 794
A37: 1. Dywidendy i inne wypłaty na rzecz właścicieli | B37: 24 490 | C37: 38 922 | D37: 18 436
A38: 2. Spłaty kredytów i pożyczek | B38: 19 931 | C38: 0 | D38: 0
A39: 3. Płatności zobowiązań z tytułu umów leasingu finansowego | B39: 68 | C39: 101 | D39: 19
A40: 4. Odsetki | B40: 271 | C40: 634 | D40: 339
...

Sheet zzwkw
A1: Zestawienie zmian w kapitale własnym
C2: w tys. zł
B3: 2018 | C3: 2019 | D3: 2020
A4: I. Kapitał własny na początek okresu (BO) | B4: 96 411 | C4: 111 812 | D4: 114 691
A5: 1. Kapitał zakładowy na początek okresu | B5: 2 429 | C5: 2 449 | D5: 2 470
A6: 1.1. Zmiany kapitału zakładowego | B6: 20 | C6: 21 | D6: 48
A7: a) zwiększenia (z tytułu) | B7: 20 | C7: 21 | D7: 48
A8: - emisji akcji (wydania udziałów) | B8: 20 | C8: 21 | D8: 48
D9: 0
A10: 1.2. Kapitał zakładowy na koniec okresu | B10: 2 449 | C10: 2 470 | D10: 2 518
A11: 2. Kapitał zapasowy na początek okresu | B11: 63 284 | C11: 70 354 | D11: 74 038
A12: 2.1. Zmiany kapitału zapasowego | B12: 7 070 | C12: 3 684 | D12: 24 991
A13: a) zwiększenia (z tytułu) | B13: 7 057 | C13: 3 709 | D13: 24 991
A14: - emisji akcji powyżej wartości nominalnej | B14: 849 | C14: 888 | D14: 2 096
A15: - z podziału zysku (ponad wymaganą ustawowo minimalną wartość) | B15: 6 208 | C15: 86 | D15: 19 747
A16: - z wyceny programu motywacyjnego | B16: 0 | C16: 2 735 | D16: 3 148
A17: b) zmniejszenia (z tytułu) | B17: -13 | C17: 25 | D17: 0
A18: - z wyceny programu motywacyjnego | B18: -13 | C18: 25 | D18: 0
A19: 2.2. Kapitał zapasowy na koniec okresu | B19: 70 354 | C19: 74 038 | D19: 99 029
A20: 3. Zysk (strata) z lat ubiegłych na początek okresu | B20: 30 698 | C20: 39 009 | D20: 38 183
A21: 3.1. Zysk z lat ubiegłych na początek okresu | B21: 30 698 | C21: 39 009 | D21: 38 183
A22: a) zmniejszenia (z tytułu) | B22: 30 698 | C22: 39 009 | D22: 38 183
A23: - dywidenda (wypłacona i zadeklarowana) | B23: 24 490 | C23: 38 923 | D23: 18 436
A24: - przeznaczenie zysku na kapitał zapasowy | B24: 6 208 | C24: 86 | D24: 19 747
A25: 3.2. Zysk z lat ubiegłych na koniec okresu | B25: 0 | C25: 0 | D25: 0
A26: 4. Wynik netto | B26: 39 009 | C26: 38 183 | D26: 30 898
A27: a) zysk netto | B27: 39 009 | C27: 38 183 | D27: 30 898
A28: II. Kapitał własny na koniec okresu (BZ ) | B28: 111 812 | C28: 114 691 | D28: 132 445
A29: III. Kapitał własny, po uwzględnieniu proponowanego podziału zysku (pokrycia straty) | B29: 82 175 | C29: 86 789 | D29: 110 283

Sheet rzis
A1: Rachunek zysków i strat
C2: w tys. zł
B3: 2018 | C3: 2019 | D3: 2020
A4: I. Przychody netto ze sprzedaży produktów, towarów i materiałów, w tym: | B4: 237 426 | C4: 222 682 | D4: 185 222
A5: - od jednostek powiązanych | B5: 3 170 | C5: 5 129 | D5: 2 251
A6: 1. Przychody netto ze sprzedaży produktów | B6: 224 247 | C6: 210 218 | D6: 176 246
A7: 2. Przychody netto ze sprzedaży towarów i materiałów | B7: 13 179 | C7: 12 464 | D7: 8 976
A8: II. Koszty sprzedanych produktów, towarów i materiałów, w tym: | B8: 149 478 | C8: 141 990 | D8: 117 696
A9: - jednostkom powiązanym | B9: 2 352 | C9: 3 839 | D9: 1 663
A10: 1. Koszt wytworzenia sprzedanych produktów | B10: 138 327 | C10: 131 782 | D10: 110 312
A11: 2. Wartość sprzedanych towarów i materiałów | B11: 11 151 | C11: 10 208 | D11: 7 384
A12: III. Zysk (strata) brutto ze sprzedaży | B12: 87 948 | C12: 80 692 | D12: 67 526
A13: IV. Koszty sprzedaży | B13: 22 717 | C13: 20 151 | D13: 18 628
A14: V. Koszty ogólnego zarządu | B14: 15 738 | C14: 16 409 | D14: 16 652
A15: VI. Zysk (strata) ze sprzedaży | B15: 49 493 | C15: 44 132 | D15: 32 246
A16: VII. Pozostałe przychody operacyjne | B16: 2 183 | C16: 3 550 | D16: 6 275
A17: 1. Zysk z tytułu rozchodu niefinansowych aktywów trwałych | B17: 0 | C17: 36 | D17: 706
A18: 2. Dotacje | B18: 2 014 | C18: 2 187 | D18: 5 450
A19: 3. Aktualizacja wartości aktywów niefinansowych | B19: 7 | C19: 1 145 | D19: 5
A20: 4. Inne przychody operacyjne | B20: 162 | C20: 182 | D20: 114
A21: VIII. Pozostałe koszty operacyjne | B21: 2 114 | C21: 1 399 | D21: 1 754
A22: 1. Strata z tytułu rozchodu niefinansowych aktywów trwałych | B22: 132 | C22: 0 | D22: 0
A23: 2. Aktualizacja wartości aktywów niefinansowych | B23: 1 298 | C23: 472 | D23: 901
A24: 3. Inne koszty operacyjne | B24: 684 | C24: 927 | D24: 853
A25: IX. Zysk (strata) z działalności operacyjnej | B25: 49 562 | C25: 46 283 | D25: 36 767
A26: X. Przychody finansowe | B26: 576 | C26: 1 102 | D26: 717
A27: 1. Odsetki, w tym: | B27: 9 | C27: 2 | D27: 1
A28: - od jednostek powiązanych | B28: 0 | C28: 0 | D28: 0
A29: 2. Aktualizacja wartości aktywów finansowych | B29: 0 | C29: 1 100 | D29: 0
A30: 3. Inne | B30: 567 | C30: 0 | D30: 716
A31: XI. Koszty finansowe | B31: 1 708 | C31: 931 | D31: 404
A32: 1. Odsetki w tym: | B32: 349 | C32: 632 | D32: 373
A33: - dla jednostek powiązanych | B33: 0 | C33: 0 | D33: 0
A34: 2. Strata z tytułu rozchodu aktywów finansowych, w tym: | B34: 0 | C34: 151 | D34: 0
A35: - w jednostkach powiązanych | B35: 0 | C35: 151 | D35: 0
A36: 3. Aktualizacja wartości aktywów finansowych | B36: 1 359 | C36: 3 | D36: 0
A37: 4. Inne | B37: 0 | C37: 145 | D37: 31
A38: XII. Zysk (strata) brutto | B38: 48 430 | C38: 46 454 | D38: 37 080
A39: XIII. Podatek dochodowy | B39: 9 421 | C39: 8 271 | D39: 6 182
A40: a) część bieżąca | B40: 9 480 | C40: 7 393 | D40: 5 787
...

Sheet analiza pionowa i pozioma
F1: Analiza pionowa i pozioma
B3: 1. Produkty gotowe | I3: 3. Towary | L3: towary/SB×100
B4: Pionowa | C4: Apion=(𝑝𝑟𝑜𝑑𝑢𝑘𝑡𝑦 𝑔𝑜𝑡𝑜𝑤𝑒)/𝑆𝐵 ×100
B5: Apion2018= | C5: =(bilans!D$20/bilans!D$30)*100 -> 14.904496 | D5: % | I5: Apion2018= | J5: =(bilans!D$21/bilans!D$30)*100 -> 1.9497335 | K5: %
B6: Apion2019= | C6: =(bilans!E$20/bilans!E$30)*100 -> 16.749634 | D6: % | I6: Apion2019= | J6: =(bilans!E$21/bilans!E$30)*100 -> 1.3429232 | K6: %
B7: Apion2020= | C7: =(bilans!F$20/bilans!F$30)*100 -> 16.933334 | D7: % | I7: Apion2020= | J7: =(bilans!F$21/bilans!F$30)*100 -> 3.0512296 | K7: %
C8: ∆A_bezw=A_I2-A_I1
B9: Pozioma | C9: ∆Awzgl=(A_I2-A_I1)/A_I1 ×100 | I9: Pozioma
B10: ∆Awzgl2018= | C10: =(bilans!D20-17312)/17312 *100 -> 43.287893 | D10: % | I10: ∆Awzgl2018= | J10: =(bilans!D21-2901)/2901 *100 -> 11.85798 | K10: %
B11: ∆Awzgl2019= | C11: =(bilans!E20-bilans!D20)/bilans!D20 * 100 -> 18.00774 | D11: % | I11: ∆Awzgl2019= | J11: =(bilans!E21-bilans!D21)/bilans!D21 *100 -> -27.673344 | K11: %
B12: ∆Awzgl2020= | C12: =(bilans!F20-bilans!E20)/bilans!E20 * 100 -> 13.920678 | D12: % | I12: ∆Awzgl2020= | J12: =(bilans!F21-bilans!E21)/bilans!E21 *100 -> 156.02897 | K12: % | P12: w tys | Q12: pln
O13: ZAPASY | P13: 2017 | Q13: 2016
B14: ∆Abez.wzgl2018= | C14: =(bilans!D20-17312) *100 -> 749400 | I14: ∆Abez.wzgl2018= | J14: =(bilans!D21-2901) *100 -> 34400 | O14: a) materiały | P14: 14569 | Q14: 13645
B15: ∆Abez.wzgl2019= | C15: =(bilans!E20-bilans!D20) * 100 -> 446700 | I15: ∆Abez.wzgl2019= | J15: =(bilans!E21-bilans!D21)*100 -> -89800 | O15: b) produkty gotowe | P15: 17312 | Q15: 18362
B16: ∆Abez.wzgl2020= | C16: =(bilans!F20-bilans!E20) * 100 -> 407500 | I16: ∆Abez.wzgl2020= | J16: =(bilans!F21-bilans!E21) *100 -> 366200 | O16: c) towary | P16: 2901 | Q16: 4641
O17: d) zaliczaki na dostawy i usługi | P17: 92 | Q17: 141
B18: Dynamika ważona | I18: Dynamika ważona | O18: zapasy razem | P18: =SUM(P14:P17) -> 34874 | Q18: =SUM(Q14:Q17) -> 36789
B19: ∆Aważ2018= | C19: =(bilans!D20-17312)/150117*100 -> 4.9921062 | I19: ∆Aważ2018= | J19: =(bilans!D21-2901)/150117 *100 -> 0.22915459 | O19: zapasy potrzebne do porównan analizy pionowej
B20: ∆Aważ2019= | C20: =(bilans!E20-bilans!D20)/bilans!E30 * 100 -> 2.5559599 | I20: ∆Aważ2019= | J20: =(bilans!E21-bilans!D21)/bilans!E30 *100 -> -0.51382404
B21: ∆Aważ2020= | C21: =(bilans!F20-bilans!E20)/bilans!F20 * 100 -> 12.219623 | I21: ∆Aważ2020= | J21: =(bilans!F21-bilans!E21)/bilans!E30 * 100 -> 2.0953493
B23: 2. Materiały | C23: (materiały/SB ) *100 | I23: 4. Zaliczki na towary i usługi | O23: pasywa razem 2017 | P23: 150117
I24: (zaliczki na towary i usługi / SB) * 100
B25: Apion2018= | C25: =(bilans!D$19/bilans!D$30)*100 -> 13.41621 | D25: % | I25: Apion2018= | J25: =(bilans!D$22/bilans!D$30)*100 -> 0.14660554 | K25: %
B26: Apion2019= | C26: =(bilans!E$19/bilans!E$30)*100 -> 10.893299 | D26: % | I26: Apion2019= | J26: =(bilans!E$22/bilans!E$30)*100 -> 0.068662455 | K26: %
B27: Apion2020= | C27: =(bilans!F$19/bilans!F$30)*100 -> 10.960866 | D27: % | I27: Apion2020= | J27: =(bilans!F$22/bilans!F$30)*100 -> 0.15284076 | K27: %
B29: Pozioma | I29: Pozioma
B30: ∆Awzgl2018= | C30: =(bilans!D19-14569)/14569 *100 -> 53.263779 | D30: % | I30: ∆Awzgl2018= | J30: =(bilans!D22-92)/92 * 100 -> 165.21739 | K30: %
B31: ∆Awzgl2019= | C31: =(bilans!E19-bilans!D19)/bilans!D19 *100 -> -14.738681 | D31: % | I31: ∆Awzgl2019= | J31: =(bilans!E22-bilans!D22)/bilans!D22 * 100 -> -50.819672 | K31: %
B32: ∆Awzgl2020= | C32: =(bilans!F19-bilans!E19)/bilans!E19 * 100 -> 13.383759 | D32: % | I32: ∆Awzgl2020= | J32: =(bilans!F22-bilans!E22)/bilans!E22 * 100 -> 150.83333 | K32: %
B34: ∆Abez.wzgl2018= | C34: =(bilans!D19-14569) *100 -> 776000 | I34: ∆Abez.wzgl2018= | J34: =(bilans!D22-92) -> 152
B35: ∆Abez.wzgl2019= | C35: =(bilans!E19-bilans!D19) *100 -> -329100 | I35: ∆Abez.wzgl2019= | J35: =(bilans!E22-bilans!D22) -> -124
B36: ∆Abez.wzgl2020= | C36: =(bilans!F19-bilans!E19) * 100 -> 254800 | I36: ∆Abez.wzgl2020= | J36: =(bilans!F22-bilans!E22) -> 181
B38: Dynamika ważona | I38: Dynamika ważona
B39: ∆Aważ2018= | C39: =(bilans!D19-14569)/150117 *100 -> 5.1693013 | I39: ∆Aważ2018= | J39: =(bilans!D22-92)/150117 *100 -> 0.10125435
B40: ∆Aważ2019= | C40: =(bilans!E19-bilans!D19)/bilans!E30 *100 -> -1.8830678 | I40: ∆Aważ2019= | J40: =(bilans!E22-bilans!D22)/bilans!E30 *100 -> -0.070951204
B41: ∆Aważ2020= | C41: =(bilans!F19-bilans!E19)/bilans!E30 * 100 -> 1.4579328 | I41: ∆Aważ2020= | J41: =(bilans!F22-bilans!E22)/bilans!E30 * 100 -> 0.10356587

Sheet dodatkowe
A1: Informacje dodatkowe
A2: Wyszczególnienie | B2: 2018 | C2: 2019 | D2: 2020
A3: Pracownicy bezpośrednio produkcyjni | B3: 429 | C3: 491 | D3: 439
A4: Pracownicy pośrednio produkcyjni | B4: 65 | C4: 66 | D4: 55
A5: Badania i rozwój, kontrola jakości, serwis | B5: 91 | C5: 109 | D5: 113
A6: Pracownicy nieprodukcyjni | B6: 141 | C6: 178 | D6: 137
A7: Razem | B7: 726 | C7: 844 | D7: 744
D8: -
A10: WYBRANE DANE FINANSOWE | B10: w tys. zł
B11: 2019 | C11: 2018 | D11: 2020
A12: I. Przychody netto ze sprzedaży produktów, towarów i materiałów | B12: 222 682 | C12: 237 426 | D12: 185222
A13: II. Zysk (strata) z działalności operacyjnej | B13: 46 283 | C13: 49 562 | D13: 36 767
A14: III. Zysk (strata) brutto | B14: 46 454 | C14: 48 430 | D14: 37 080
A15: IV. Zysk (strata) netto | B15: 38 183 | C15: 39 009 | D15: 30 898
A16: V. Przepływy pieniężne netto z działalności operacyjnej | B16: 41 601 | C16: 50 690 | D16: 18 841
A17: VI. Przepływy pieniężne netto z działalności inwestycyjnej | B17: -23 527 | C17: -21 554 | D17: -15 943
A18: VII. Przepływy pieniężne netto z działalności finansowej | B18: -20 421 | C18: -42 440 | D18: -2 931
A19: VIII. Przepływy pieniężne netto, razem | B19: -2 347 | C19: -13 304 | D19: -33
A20: IX. Aktywa, razem | B20: 174 768 | C20: 166 433 | D20: 196 937
A21: X. Zobowiązania i rezerwy na zobowiązania | B21: 60 077 | C21: 54 621 | D21: 64 492
A22: XI. Zobowiązania długoterminowe | B22: 0 | C22: 51 | D22: 0
A23: XII. Zobowiązania krótkoterminowe | B23: 40 892 | C23: 31 047 | D23: 48 295
A24: XIII. Kapitał własny | B24: 114 691 | C24: 111 812 | D24: 132 445
A25: XIV. Kapitał zakładowy | B25: 2 470 | C25: 2 449 | D25: 2 518
A26: XV. Liczba akcji (w szt.) | B26: 9 878 783 | C26: 9 796 133 | D26: 10073683
A27: XVI. Zysk (strata) na jedną akcję zwykłą (w zł/ EUR) | B27: 3,87 | C27: 3,99 | D27: 3,10
A28: XVII. Rozwodniony zysk (strata) na jedną akcję zwykłą (w zł/EUR) | B28: 3,80 | C28: 3,92 | D28: 3,10
A29: XVIII. Wartość księgowa na jedną akcję (w zł/EUR) | B29: 11,61 | C29: 11,41 | D29: 13,15
A30: XIX. Rozwodniona wartość księgowa na jedną akcję (w zł/EUR) | B30: 11,40 | C30: 11,22 | D30: 13,15
A31: WYBRANE DANE FINANSOWE | B31: w tys. zł
B32: 2019 | C32: 2018
A33: Zadeklarowana lub wypłacona dywidenda na jedną akcję (w XX. zł/EUR) | B33: 3,94 | C33: 2,50 | D33: 1,85
B35: srednia cena akcji
B37: 2018 | C37: 2019 | D37: 2020
B38: 41.31 | C38: 46.36 | D38: 40.38

Sheet Wskaźnik rentowności
A1: Wskaźniki rentowności
A2: 1) Rentowność brutto sprzedaży | H2: RS=(Wynik ze sprzedaży)/(Przychody netto ze sprzedaży produktów i towarów)*100
A3: Wskaźniki branżowe | D3: Określa jaką część przychodów ze sprzedaży firmy stanowi jej zysk(strata) czyli podaje on wielkość marży zysku (straty) w stosunku do przychodów ze sprzedaży produktów i towarów.
A4: 0.0556 | B4: RS2018 | D4: Wielkość marży zysku (straty) w stosunku do przychodow ze sprzedaży produktów i towartów wynosi 20,85 i była wyższa od średniej w branży
B5: =rzis!B15/(rzis!B6+rzis!B7)*100 -> 20.845653
A6: 0.0528 | B6: RS2019 | D6: Wielkość marży zysku (straty) w stosunku do przychodow ze sprzedaży produktów i towartów wynosi 19,81 i była wyższa od średniej w branży
B7: =rzis!C15/(rzis!C6+rzis!C7)*100 -> 19.818396
A8: 0.053 | B8: RS2020 | D8: Wielkość marży zysku (straty) w stosunku do przychodow ze sprzedaży produktów i towartów wynosi 17,40 i była wyższa od średniej w branży
B9: =rzis!D15/(rzis!D6+rzis!D7)*100 -> 17.409379
A11: Zmiana RS:
A12: RS2019-RS2018= | B12: =B7-B5 -> -1.0272572 | C12: Wskaźnik malał, więc ocena negatywna
A13: RS2020-RS2019= | B13: =B9-B7 -> -2.4090167 | C13: Wskaźnik malał, więc ocena negatywna
A16: 2) Zyskowność netto sprzedaży | F16: 𝑍𝐷=(𝑊𝑦𝑛𝑖𝑘 𝑓𝑖𝑛𝑎𝑛𝑠𝑜𝑤𝑦 𝑛𝑒𝑡𝑡𝑜)/(𝑃𝑟𝑧𝑦𝑐ℎ𝑜𝑑𝑦 𝑧 𝑜𝑔ół𝑢 𝑑𝑧𝑖𝑎ł𝑎𝑙𝑛𝑜ś𝑐𝑖)*100
A17: Wskaźniki branżowe | D17: Informuje o udziale zysku (straty) po opodatkowaniu w wartości przychodów z całokształtu działalności, czyli o marży zysku (straty) netto na przychodach.
A18: 0.0475 | B18: ZD2018 | D18: udział zysku po opodatkowaniu w wartości przychodów z całokształtu działalności wynosił 16,24% i był wyższy od średniej w branży
B19: =rzis!B42/(rzis!B26+rzis!B16+rzis!B4) *100 -> 16.241231
A20: 0.0444 | B20: ZD2019 | D20: udział zysku po opodatkowaniu w wartości przychodów z całokształtu działalności wynosił 16,80% i był wyższy od średniej w branży
B21: =rzis!C42/(rzis!C26+rzis!C16+rzis!C4) *100 -> 16.795992
A22: 0.0421 | B22: ZD2020 | D22: udział zysku po opodatkowaniu w wartości przychodów z całokształtu działalności wynosił 16,1% i był wyższy od średniej w branży
B23: =rzis!D42/(rzis!D26+rzis!D16+rzis!D4) *100 -> 16.074792
A25: Zmiana RS:
A26: ZD2019-ZD2018= | B26: =B21-B19 -> 0.55476108 | C26: Wskaźnik rósł, więc ocena pozytywna.
A27: ZD2020-ZD2019= | B27: =B23-B21 -> -0.72120016 | C27: Wskaźnik malał, więc ocena negatywna
A30: 3) Rentowność pracy | D30: 𝑍𝐷=(𝑊𝑦𝑛𝑖𝑘 𝑓𝑖𝑛𝑎𝑛𝑠𝑜𝑤𝑦 𝑛𝑒𝑡𝑡𝑜)/(𝑃𝑟𝑧𝑦𝑐ℎ𝑜𝑑𝑦 𝑧 𝑜𝑔ół𝑢 𝑑𝑧𝑖𝑎ł𝑎𝑙𝑛𝑜ś𝑐𝑖)*100
A31: Wskaźniki branżowe | D31: Określa relacje między wynikiem finansowym netto jednostki a przeciętnym stanem zatrudnienia.
B32: RP2018 | D32: Rentowność pracy wynosiła 53,73 tyś zł
B33: =rzis!B42/(dodatkowe!B7) -> 53.731405
B34: RP2019 | D34: Rentowność pracy wynosiła 48,64 tyś zł
B35: =rzis!C42/((dodatkowe!C7+dodatkowe!B7)/2) -> 48.640764
B36: RP2020 | D36: Rentowność pracy wynosiła 40,1 tyś zł
B37: =rzis!D42/((dodatkowe!B7+dodatkowe!C7+dodatkowe!D7)/3) -> 40.057908
A39: Zmiana RS:
A40: RP2019-RP2018= | B40: =B35-B33 -> -5.0906406 | C40: Wskaźnik malał, więc ocena negatywna
A41: RP2020-RP2019= | B41: =B37-B35 -> -8.5828559 | C41: Wskaźnik malał, więc ocena negatywna
A44: 4) Zyskowność ogółu majątku | F44: 𝑍𝑂𝑀=(𝑊𝑦𝑛𝑖𝑘 𝑓𝑖𝑛𝑎𝑛𝑠𝑜𝑤𝑦 𝑛𝑒𝑡𝑡𝑜)/(𝑀𝑎𝑗ą𝑡𝑒𝑘 𝑜𝑔ół𝑒𝑚 (ś𝑟))*100
A45: Wskaźniki branżowe | D45: Wskaźnik ten charakteryzuje efektywność wykorzystania ogółu majątku tj. jego zdolność do tworzenia zysku.
A46: 0.063 | B46: ZOM2018 | D46: Wynik działaności jednostki przypadający na jednostke majątku wynosi 23,4% i był wyższy od średniej w branży
B47: =rzis!B42/(bilans!D30) *100 -> 23.43826
A48: 0.0577 | B48: ZOM2019 | D48: Wynik działaności jednostki przypadający na jednostke majątku wynosi 22,4 % i był wyższy od średniej w branży
B49: =rzis!C42/((bilans!D30+bilans!E30)/2) * 100 -> 22.381529
...

Sheet Wskaźnik płynności
A1: Wskaźniki płynności
A2: 1) Wskaźnik płynności | D2: WPI=(Aktywa obrotowe)/(Zobowiązania krótkoterminowe)
A3: wskaźniki branżowe | B3: 1) Wskaźnik płynności 1 | D3: Płynnośc miesięczna- Pozwala na ocenę możliwośc
A4: 0.29 | B4: WPI 2018 | D4: i spłaty zobowiązań krótkoterminowych dzięki upłynnieniu środków obrotowych.
B5: =bilans!D17/bilans!D46 -> 2.4648758
A6: 0.32 | B6: WPI2019 | D6: We wszystkich podanych latach WPI jest wyższe niż w przeciętnych wskaźnikach branżowych
B7: =bilans!E17/bilans!E46 -> 1.7896655
A8: 0.35 | B8: WPI2020
B9: =bilans!F17/bilans!F46 -> 1.8402733
B13: WPI2020-WPI2019= | C13: =B9-B7 -> 0.05060786 | D13: wskaźnik wzrósł ocena pozytywba
B14: WPI2019-WPI2018= | C14: =B7-B5 -> -0.67521037 | D14: wskaźnik malał ocena negatywna
A16: 2) Wskaźnik płynności II | D16: WPII=(Aktywa obrotowe-Zapasy)/(Zobowiązania krótkoterminowe)
A17: wskaźniki branżowe | B17: WPII 2018 | D17: Płynność tygodniowa
A18: 0.93 | B18: =(bilans!D17-bilans!D18)/bilans!D46 -> 0.83431571
B19: WPII2019
A20: 0.93 | B20: =(bilans!E17-bilans!E18)/bilans!E46 -> 0.54790668 | D20: We wszystkich podanych latach WPII jest niższe niż w przeciętnych wskaźnikach branżowych
B21: WPII2020
A22: 0.97 | B22: =(bilans!F17-bilans!F18)/bilans!F46 -> 0.57215033
B26: WPII2020-WPII2019= | C26: =B22-B20 -> 0.024243645 | D26: wskaźnik wzrósł ocena pozytywna
B27: WPII2019-WPII2018= | C27: =B20-B18 -> -0.28640903 | D27: wskaźnik malał ocena negatywna
A29: 3) Wskaźnik zdolności płatniczej | D29: WZP=(środki pieniężne+krótkoterminowe papiery wartościowe)/(zobowiązania krótkoterminowe)
A30: wskaźniki branżowe | B30: WZP 2018 | D30: Płynność dzienna
A31: 1.48 | B31: =bilans!D26/bilans!D46 -> 0.15183432
B32: WZP 2019
A33: 1.48 | B33: =bilans!E26/bilans!E46 -> 0.057566272 | D33: We wszystkich latach WZP jest niższe od przeciętnych wartości w branży
B34: WZP 2020
A35: 1.53 | B35: =bilans!F26/bilans!F46 -> 0.049218346
B39: WZP2020-WZP2019= | C39: =B35-B33 -> -0.0083479265 | D39: wskaźnik malał ocena negatywna
B40: WZP2019-WZP2018= | C40: =B33-B31 -> -0.094268044 | D40: wskaźnik malał ocena negatywna

Sheet Wskaźniki obrotowości
A1: Wskaźniki obrotowości
A2: 1) Wskaźnik rotacji należności | E2: WRN=(Przychody netto ze sprzedaży produktów i towarów)/(Należności i roszczenia przeciętne)
A3: wskaźniki branżowe | D3: Wskaźnik ten określa liczbę cykli inkasa przeciętnego stanu należności a podstawę stanowią przychody ze sprzedaży
A4: 54 | B4: WRN2018
B5: =(rzis!B6+rzis!B7)/(bilans!D23) -> 13.188135
A6: 53 | B6: WRN2019 | D6: w każdym z lat wskaźnik jest zbyt mały co wskazuje na niską efektywność
B7: =(rzis!C6+rzis!C7)/((bilans!D23 +bilans!E23)/2) -> 13.184251 | D7: zarządzania zapasami lub problemów z popytem na produkty
A8: 57 | B8: WRN2020
B9: =(rzis!D6+rzis!D7)/((bilans!D23 + bilans!E23 +bilans!F23)/3) -> 10.458217
A11: Zmiana WRN:
A12: WRN2019-WRN2018= | B12: =B7-B5 -> -0.0038842747 | C12: wskaźnik malał ocena negatywna
A13: WRN2020-WRN2019= | B13: =B9-B7 -> -2.7260338 | C13: wskaźnik malał ocena negatywna
A16: 2) Wskaźnik obrotu należnościami | E16: 𝑊𝑂𝑁=360/𝑊𝑅𝑁
D17: Wskaźnik ten określa długość cyklu inkasa należności w dniach czyli ilość dni sprzedaży
B18: WON2018 | D18: za którą nie otrzymano jeszcze należności (czas zamrożenia środków pieniężnych w należnościach).
B19: =360/B5 -> 27.297263 | D19: ac .sa otrzymywał należności w 2018 co 27,29 dni
B20: WON2019
B21: =360/B7 -> 27.305305 | D21: ac .sa otrzymywał należności w 2019 co 27,30 dni
B22: WON2020
B23: =360/B9 -> 34.422693 | D23: ac .sa otrzymywał należności w 2020 co 43,42 dni
A25: Zmiana WON:
A26: WON2019-WON2018= | B26: =B21-B19 -> 0.008042176 | C26: wskaźnik wzrósł ocena pozytywna
A27: WON2020-WON2019= | B27: =B23-B21 -> 7.1173874 | C27: wskaźnik wzrósł ocena pozytywna
A30: 3) Wskaźnik rotacji zapasów | D30: WRZ=(koszt sprzedanych produktów i towarów)/(przeciętny stan zapasów)
A31: wskaźniki branżowe | D31: Wskaźnik ten świadczy o efektywności gospodarowania zapasami
A32: 44 | B32: WRZ 2018 | D32: i podaje ile razy w ciągu roku następuje “odnowienie “ stanu zapasów.
B33: =rzis!B8/bilans!D18 -> 2.9527102
A34: 44 | B34: WRZ 2019 | D34: W każdym z lat wskaźnik rotacji zapasów jest znacząco niższy
B35: =rzis!C8/((bilans!D18+bilans!E18)/2) -> 2.8005365 | D35: od średniej co pokazuje istotne problemy z efektywnością zarządzania zapasami
A36: 48 | B36: WRZ 2020
B37: =rzis!D8/((bilans!D18+bilans!E18+bilans!F18)/3) -> 2.1708988
A39: Zmiana WRZ:
A40: WRZ2019-WRZ2018= | B40: =B35-B33 -> -0.1521737 | C40: wskaźnik malał ocena negatywna
A41: WRZ2020-WRZ2019= | B41: =B37-B35 -> -0.62963772 | C41: wskaźnik malał ocena negatywna
A44: 4) Wskaźnik obrotu zapasami w dniach | F44: WOZ=360/WRZ
D45: Określa długość cyklu obrotu zapasami w dniach. Obrazuje on zamrożenie kapitałów w finansowaniu zapasów.
B46: WOZ2018
B47: =360/B33 -> 121.92189 | D47: Długość cyklu obrotu zapasami w dniach w 2018 roku wynosiła 121,92 dni
B48: WOZ2019
B49: =360/B35 -> 128.5468 | D49: Długość cyklu obrotu zapasami w dniach w 2019 roku wynosiła 128,54 dni
...

Sheet Wskaźniki zadłużenia
A1: Wskaźniki zadłużenia
A2: 1) Pokrycie odsetek zyskiem | E2: 𝑃𝑂𝑍=(𝑧𝑦𝑠𝑘 𝑏𝑟𝑢𝑡𝑡𝑜+𝑜𝑑𝑠𝑒𝑡𝑘𝑖 𝑑𝑜 𝑧𝑎𝑝ł𝑎𝑐𝑒𝑛𝑖𝑎)/(𝑜𝑑𝑠𝑒𝑡𝑘𝑖 𝑑𝑜 𝑧𝑎𝑝ł𝑎𝑐𝑒𝑛𝑖𝑎)
A3: Wskaźniki branżowe | D3: Wskaźnik ten określa relacje pomiędzy zyskiem brutto a odsetkami płaconymi od kapitałów obcych.
B4: POZ2018
B5: =(rzis!B38+rzis!B32)/rzis!B32 -> 139.76791
B6: POZ2019 | E6: wszystkie wskaźniki przekraczają poziom pokrycia odesetek więc poziom jest bardzo zadowalający
B7: =(rzis!C38+rzis!C32)/rzis!C32 -> 74.503165
B8: POZ2020
B9: =(rzis!D38+rzis!D32)/rzis!D32 -> 100.41019
A11: Zmiana RS:
A12: POZ2019-POZ2018= | B12: =B7-B5 -> -65.264744 | D12: wskaźnik malał ocena negatywna
A13: POZ2020-POZ2019= | B13: =B9-B7 -> 25.907023 | D13: wskaźnik wzrósł ocena pozytywna
B15: Zadowalający poziom wynosi [4-5]
A16: 2) Pokrycie obsługi długu | E16: POD=(zysk brutto+odsetki do zapłacenia)/(raty kapitałowe+odsetki do zapłacenia)
D17: Wskaźnik ten informuje o możliwości obsługi kredytu, podając ile razy nieopodatkowana
B18: POD2018 | D18: nadwyżka finansowa powiększona o odsetki pokrywa płatności kredytowe.
B19: =(rzis!B38+rzis!B32)/(rzis!B32+rpp!B38) -> 2.4052761
B20: POD2019 | D20: w każdym z lat firma ma dużą zdolność do spłacenia swojego zadłużenia z wygenerowanych dochodów
B21: =(rzis!C38+rzis!C32)/(rzis!C32+rpp!C38) -> 74.503165
B22: POD2020
B23: =(rzis!D38+rzis!D32)/(rzis!D32+rpp!D38) -> 100.41019
A25: Zmiana RS:
A26: POD2019-POD2018= | B26: =B21-B19 -> 72.097888 | D26: wskaźnik wzrósł ocena pozytywna
A27: POD2020-POD2019= | B27: =B23-B21 -> 25.907023 | D27: wskaźnik wzrósł ocena pozytywna
B29: bezpieczny poziom od 1,5
A30: 3) Stopa zadłużenia
A31: 𝑆𝑍=(𝑧𝑜𝑏𝑜𝑤𝑖ą𝑧𝑎𝑛𝑖𝑎 𝑜𝑔ół𝑒𝑚)/(𝑚𝑎𝑗ą𝑡𝑒𝑘 𝑜𝑔ół𝑒𝑚)*100
A32: Wskaźniki branżowe | B32: WRZ 2018 | D32: Wskaźnik ten określa w jakiej części majątek firmy jest
A33: 0.4723 | B33: =bilans!D36/bilans!D30 *100 -> 32.818612 | D33: pokrywany z zobowiązań (krótkoterminowych i długoterminowych).
B34: WRZ 2019
A35: 0.4749 | B35: =bilans!E36/bilans!E30 *100 -> 34.375286 | D35: Wartości pochodzenia majątku firmy z zobowiązań w każdym roku są lepsze niż wartości branżowe
B36: WRZ 2020
A37: 0.481 | B37: =bilans!F36/bilans!F30 *100 -> 32.747528
A39: Zmiana RS:
A40: WRZ2019-WRZ2018= | B40: =B35-B33 -> 1.5566744 | D40: wskaźnik wzrósł ocena pozytywna
A41: WRZ2020-WRZ2019= | B41: =B37-B35 -> -1.6277577 | D41: wskaźnik malał ocena negatywna
A43: 4) Zadłużenie kapitałów własnych
D44: 𝑍𝐴𝐾𝑊=(𝑧𝑜𝑏𝑜𝑤𝑖ą𝑧𝑎𝑛𝑖𝑎 𝑜𝑔ół𝑒𝑚)/(𝑘𝑎𝑝𝑖𝑡𝑎ł𝑦 𝑤ł𝑎𝑠𝑛𝑒)*100
A45: wskaźniki branżowe | D45: Wskaźnik ten określa w jakiej części kapitały własne pokrywają zobowiązania ogółem
B46: ZAKW2018 | D46: Majątek tej firmy jest pokrywany ze zobowiązań w 48,9% co jest wynikiem lepszym niż średnia branżowa
...

Sheet Wskaźniki rynku kapitałowego
A1: Wskaźniki rynku kapitałowego
A2: 1) Cena do zysku na jedną akcję | D2: P / E=(cena rynkowa jednej akcji)/(zysk na jedną akcję)
A4: P/E= | B4: P/E 2018 | C4: =H7/dodatkowe!B27 -> 0.010674419 | H4: srednia cena akcji
B6: P/E 2019 | C6: =I7/dodatkowe!C27 -> 0.011619048 | H6: 2018 | I6: 2019 | J6: 2020
G7: srednia cena w tys pln | H7: =41.31/1000 -> 0.04131 | I7: =46.36/1000 -> 0.04636 | J7: =40.38/1000 -> 0.04038
B8: P/E 2020 | C8: =J7/dodatkowe!D27 -> 0.013025806 | G8: liczba akcji | H8: =dodatkowe!B26 -> 9 878 783 | I8: =dodatkowe!C26 -> 9 796 133 | J8: =dodatkowe!D26 -> 10073683
H9: 2018 | I9: 2019 | J9: 2020
A10: 2) Mnożnik cenowy | G10: wartksc majatku akcje | H10: =bilans!D30/dodatkowe!B26 -> 0.016847521 | I10: =bilans!E30/dodatkowe!C26 -> 0.017840509 | J10: =bilans!F30/dodatkowe!D26 -> 0.019549652
A11: C/WK=(𝑐𝑒𝑛𝑎 𝑟𝑦𝑛𝑘𝑜𝑤𝑎 𝑗𝑒𝑑𝑛𝑒𝑗 𝑎𝑘𝑐𝑗𝑖)/(𝑤𝑎𝑟𝑡𝑜ś𝑐 𝑚𝑎𝑗ą𝑡𝑘𝑢 𝑛𝑎 𝑗𝑒𝑑𝑛ą 𝑎𝑘𝑐𝑗ę) | G11: Zadeklarowana lub | H11: =3.94/1000 -> 0.00394 | I11: =2.5/1000 -> 0.0025 | J11: =1.85/1000 -> 0.00185
A12: wartość majątku na jedną akcję | G12: wypłacona dywidenda
B13: C/WK2018 | C13: =H7/H10 -> 2.4519928 | G13: na jedną akcję w tys pln
B15: C/WK2019 | C15: =I7/I10 -> 2.5985806
B17: C/WK2020 | C17: =J7/J10 -> 2.0655099
A20: 3) Zysk na jedną akcję | C20: EPS=Zysk netto/Ilość akcji nieuprzywilejowanych
B22: EPS2018 | C22: =rzis!B42/H8 -> 0.0039487658
B24: EPS2019 | C24: =rzis!C42/I8 -> 0.0038977625
B26: EPS2020 | C26: =rzis!D42/J8 -> 0.0030672
A29: 4) Stopa dywidendy | C29: DPS=Wartość dywidendy na jedną akcję/Cena rynkowa jednej akcji
B30: %
B31: DPS2018 | C31: =H11/H7 -> 0.095376422
B33: DPS2019 | C33: =I11/I7 -> 0.053925798
B35: DPS2020 | C35: =J11/J7 -> 0.04581476
A38: 5) Udział dywidendy w zysku | D38: DP=(Wartość dywidendy na jedną akcję/Zysk netto na jedną akcję)∙100%
B39: %
B40: DP2018 | C40: =H11/dodatkowe!B27 *100 -> 0.10180879
B42: DP2019 | C42: =I11/dodatkowe!C27 *100 -> 0.062656642
B44: DP2020 | C44: =J11/dodatkowe!D27 *100 -> 0.059677419

Sheet model du ponta
A1: Model du ponta
A6: Wyszczególnienie | B6: rok 2018 | C6: rok 2019 | D6: rok 2020
A7: Zyskowność netto działalności (ZD) | B7: ='Wskaźnik rentowności'!B19 -> 16.241231 | C7: ='Wskaźnik rentowności'!B21 -> 16.795992 | D7: ='Wskaźnik rentowności'!B23 -> 16.074792
A8: Rotacja majątu (RM) | B8: ='Wskaźniki obrotowości'!B88 -> 1.4431333 | C8: ='Wskaźniki obrotowości'!B90 -> 0.66627589 | D8: ='Wskaźniki obrotowości'!B92 -> 0.35718347
A9: Struktura kapitałów własnych (SKW) | B9: =bilans!D30/bilans!D32 -> 1.4885075 | C9: =bilans!E30/bilans!E32 -> 1.5238162 | D9: =bilans!F30/bilans!F32 -> 1.4869342
A10: Kapitał ogółem | B10: =bilans!D30 -> 166 433 | C10: =bilans!E30 -> 174 768 | D10: =bilans!F30 -> 196 937
A11: Kapitał własny | B11: =bilans!D32 -> 111 812 | C11: =bilans!E32 -> 114 691 | D11: =bilans!F32 -> 132 445
A12: Zysk netto | B12: =rzis!B42 -> 39 009 | C12: =rzis!C42 -> 38 183 | D12: =rzis!D42 -> 30 898
A13: Przychody | B13: =rzis!B4+rzis!B16+rzis!B26 -> 240185 | C13: =rzis!C4+rzis!C16+rzis!C26 -> 227334 | D13: =rzis!D4+rzis!D16+rzis!D26 -> 192214
A14: Zyskownośc kapitałów własnych (ZKW) | B14: ='Wskaźnik rentowności'!B61 -> 34.888026 | C14: ='Wskaźnik rentowności'!B63 -> 33.715227 | D14: ='Wskaźnik rentowności'!B65 -> 25.823796
A15: Δ Zyskowność kapitałów własnych (ΔZKW) | B15: 2019-2018 = -1,1728, 2020-2019 = -7,89143, 2020-2018 = -9,064230
A18: ZKW=ZD*RM*SKW | B18: Polityka marżowa: | C18: Efektywność wykorzystania majątku: | D18: Dźwignia finansowa | E18: Ocena zmiany:
A19: ZKW2018<ZKW2019 | B19: Wzrosła | C19: zmalała | D19: wzrosła | E19: pozytywna
A20: ZKW2019<ZKW2020 | B20: zmalała | C20: zmalała | D20: zmalała | E20: pozytywna

Sheet Model Artmana, analiza dyskrymi
A1: Model artmana, analiza dyskryminacyjna, analiza nierówności indeksów
A2: MODEL ARTMANA
A3: Wskaźniki | B3: WZÓR | C3: 2018 | D3: 2019 | E3: 2020
A4: X_1 | B4: Kapitał pracujący/Majątek ogółem | C4: =(bilans!D17-bilans!D46)/bilans!D30 -> 0.27326311 | D4: =(bilans!E17-bilans!E46)/bilans!E30 -> 0.18476495 | E4: =(bilans!F17-bilans!F46)/bilans!F30 -> 0.20606082
A5: X_2 | B5: Zysk zatrzymany/Majątek ogółem | C5: =(bilans!D35+bilans!D34)/bilans!D30 -> 0.65709925 | D5: =(bilans!E35+bilans!E34)/bilans!E30 -> 0.64211412 | E5: =(bilans!F35+bilans!F34)/bilans!F30 -> 0.6597389
A6: X_3 | B6: EBIT/Majątek ogółem | C6: =rzis!B15/bilans!D30 -> 0.29737492 | D6: =rzis!C15/bilans!E30 -> 0.25251762 | E6: =rzis!D15/bilans!F30 -> 0.16373764
A7: X_4 | B7: Wartość rynkowa kapitału akcyjnego/Wartość księgowa zadłużenia | C7: =bilans!D33/bilans!D36 -> 0.044836235 | D7: =bilans!E33/bilans!E36 -> 0.041113904 | E7: =bilans!F33/bilans!F36 -> 0.039043602
A8: X_5 | B8: Przychody ze sprzedaży/Majątek ogółem | C8: =rzis!B4/bilans!D30 -> 1.426556 | D8: =rzis!C4/bilans!E30 -> 1.2741577 | E8: =rzis!D4/bilans!F30 -> 0.94051397
C9: =1.2*C4+1.4*C5+3.3*C6+0.6*C7+1*C8 -> 3.6826497 | D9: =1.2*D4+1.4*D5+3.3*D6+0.6*D7+1*D8 -> 3.2528119 | E9: =1.2*E4+1.4*E5+3.3*E6+0.6*E7+1*E8 -> 2.6751818
A13: ANALIZA DYSKRYMINACYJNA
A14: Wskaźniki | B14: Wzór | C14: 2018 | D14: 2019 | E14: 2020
A15: WPI | B15: Majątek obrotowy/Zobowiązania krótkoterminowe | C15: ='Wskaźnik płynności'!B5 -> 2.4648758 | D15: ='Wskaźnik płynności'!B7 -> 1.7896655 | E15: ='Wskaźnik płynności'!B9 -> 1.8402733
A16: SZ | B16: (Zobowiązania ogółem/Suma bilansowa)*100 | C16: ='Wskaźniki zadłużenia'!B33 -> 32.818612 | D16: ='Wskaźniki zadłużenia'!B35 -> 34.375286 | E16: ='Wskaźniki zadłużenia'!B37 -> 32.747528
A17: RM | B17: Przychody z ogółu działalności/Majątek ogółem | C17: ='Wskaźniki obrotowości'!B88 -> 1.4431333 | D17: ='Wskaźniki obrotowości'!B90 -> 0.66627589 | E17: ='Wskaźniki obrotowości'!B92 -> 0.35718347
A18: ZOM | B18: (Zysk netto/Majątek ogółem)*100 | C18: ='Wskaźnik rentowności'!B47 -> 23.43826 | D18: ='Wskaźnik rentowności'!B49 -> 22.381529 | E18: ='Wskaźnik rentowności'!B51 -> 17.22495
A19: WOZO | B19: (Zobowiązania krótkoterminowe/Koszt sprzedanych produktów,towarów i materiałów)*360 | C19: ='Wskaźniki obrotowości'!B61 -> 74.77301 | D19: ='Wskaźniki obrotowości'!B63 -> 50.506814 | E19: ='Wskaźniki obrotowości'!B65 -> 42.492008
C20: =0.605+0.681*C15-0.0196*C16+0.157*C17+0.00969*C18+0.000672*C19 -> 2.1442718 | D20: =0.605+0.681*D15-0.0196*D16+0.157*D17+0.00969*D18+0.000672*D19 -> 1.5054295 | E20: =0.605+0.681*E15-0.0196*E16+0.157*E17+0.00969*E18+0.000672*E19 -> 1.4679168
A23: ANALIZA NIERÓWNOŚCI INDEKSÓW
A24: INDEKSY | B24: WZÓR | C24: 2018-2019 | D24: 2019-2020
A25: IR | B25: Zatrudnienie (rok2)/Zatrudnienie (rok1) | C25: =dodatkowe!C7/dodatkowe!B7 -> 1.1625344 | D25: =dodatkowe!D7/dodatkowe!C7 -> 0.88151659
A26: IM | B26: Majątek (rok2)/Majątek (rok1) | C26: =bilans!E30/bilans!D30 -> 1.0500802 | D26: =bilans!F30/bilans!E30 -> 1.1268482
A27: IK | B27: Koszty (rok2)/Koszty (rok1) | C27: =(rzis!C8+rzis!C13+rzis!C14+rzis!C21+rzis!C31)/(rzis!B8+rzis!B13+rzis!B14+rzis!B21+rzis!B31) -> 0.94328701 | D27: =(rzis!D8+rzis!D13+rzis!D14+rzis!D21+rzis!D31)/(rzis!C8+rzis!C13+rzis!C14+rzis!C21+rzis!C31) -> 0.85766254
A28: IP | B28: Przychody (rok2)/Przychody (rok1) | C28: =(rzis!C4+rzis!C16+rzis!C26)/(rzis!B4+rzis!B16+rzis!B26) -> 0.94649541 | D28: =(rzis!D4+rzis!D16+rzis!D26)/(rzis!C4+rzis!C16+rzis!C26) -> 0.84551365
A29: IZ | B29: Zysk netto (rok2)/Zysk netto (rok1) | C29: =bilans!E35/bilans!D35 -> 0.9788254 | D29: =bilans!F35/bilans!E35 -> 0.80920829
A30: Żadna z relacji nie jest zachowana | C30: Iz<Ik<Ip<Ir<Im | D30: Ik<Ip<Im<Ir<Iz
B31: firma nie spełnia wzorca dynamiki, co oznacza, że wydatki, przychody czy zyski netto nie rosną w harmonijny sposób.

Sheet SWOT
A1: ANALIZA SWOT DLA AC.SA
A3: MOCNE STRONY
A4: Stabilne przychody
A6: Wysoka rentowność
A8: Znacząca działalność eksportowa
A10: SŁABE STRONY
A11: Zależność od rynku motoryzacyjnego
A13: Niższa efektywność zarządzania zapasami
A15: Wysokie koszty stałe
A17: SZANSE
A18: Rozwój technolohii i innowacji
A20: Ekspansja na rynki zagraniczne
... A30: kursów walutowych przez spory eksport firmy)
